2023-12-07 18:38:09,534 [+] pydumpck is a multi-threads tool for decompile exe,elf,pyz,pyc packed by python which is base on pycdc and uncompyle6.sometimes its py-file result not exactly right ,maybe could use uncompyle6.
--------------------
pydumpck initilizing with 1.17.9 :pyinstaller_dump.py:115-20  /usr/local/lib/python3.8/dist-packages/pydumpck/pyinstaller_dump.py on(pyinstaller_dump.run) at 762@MainThread  
2023-12-07 18:38:09,535 [*] plugins loaded with ['pycdc'] :__init__.py:155-10  /usr/local/lib/python3.8/dist-packages/pydumpck/py_common_dump/__init__.py on(__init__.load_plugins) at 762@MainThread  
2023-12-07 18:38:09,535 [*] target file input:./crackme4
to:output_2385117 :__init__.py:190-10  /usr/local/lib/python3.8/dist-packages/pydumpck/py_common_dump/__init__.py on(__init__.main) at 762@MainThread  
2023-12-07 18:38:09,536 [*] start dump target file. type:pyc :__init__.py:203-10  /usr/local/lib/python3.8/dist-packages/pydumpck/py_common_dump/__init__.py on(__init__.main) at 762@MainThread  
2023-12-07 18:38:12,540 [+] find suitable python-version:(3, 7),magic:3394 :__init__.py:41-20  /usr/local/lib/python3.8/dist-packages/pydumpck/pyc_checker/pyc/__init__.py on(__init__.check_marshal) at 762@MainThread  
2023-12-07 18:38:12,541 [-] pycdc_file not exist , trying build it... :__init__.py:21-40  /usr/local/lib/python3.8/dist-packages/pydumpck/pyc_checker/lib_pycdc/__init__.py on(__init__.use_pycdc) at 762@MainThread  
2023-12-07 18:38:17,546 [*] no cache exist , start build :build.py:51-10  /usr/local/lib/python3.8/dist-packages/pydumpck/pyc_checker/lib_pycdc/build.py on(build.build) at 762@MainThread  
2023-12-07 18:38:18,038 [*] moving pycdc file /usr/local/lib/python3.8/dist-packages/pydumpck/pyc_checker/lib_pycdc/src/output/pycdc , has cache:/usr/local/lib/python3.8/dist-packages/pydumpck/pyc_checker/lib_pycdc/pycdc :build.py:57-10  /usr/local/lib/python3.8/dist-packages/pydumpck/pyc_checker/lib_pycdc/build.py on(build.build) at 762@MainThread  
2023-12-07 18:38:18,039 [-] error on migrating..[Errno 2] No such file or directory: '/usr/local/lib/python3.8/dist-packages/pydumpck/pyc_checker/lib_pycdc/src/output/pycdc' :build.py:63-40  /usr/local/lib/python3.8/dist-packages/pydumpck/pyc_checker/lib_pycdc/build.py on(build.build) at 762@MainThread  
2023-12-07 18:38:18,039 [*] completed built :build.py:65-10  /usr/local/lib/python3.8/dist-packages/pydumpck/pyc_checker/lib_pycdc/build.py on(build.build) at 762@MainThread  
2023-12-07 18:38:18,039 [+] get compile file path:/usr/local/lib/python3.8/dist-packages/pydumpck/pyc_checker/lib_pycdc/pycdc,is_build:True :__init__.py:25-20  /usr/local/lib/python3.8/dist-packages/pydumpck/pyc_checker/lib_pycdc/__init__.py on(__init__.use_pycdc) at 762@MainThread  
2023-12-07 18:38:18,039 [!] Exception on decompile bytecode file:output_2385117/crackme4,with error:[Errno 2] No such file or directory: '/usr/local/lib/python3.8/dist-packages/pydumpck/pyc_checker/lib_pycdc/pycdc' :__init__.py:45-30  /usr/local/lib/python3.8/dist-packages/pydumpck/py_package/package_struct/__init__.py on(__init__.decompile_pyc) at 762@MainThread  
2023-12-07 18:38:18,040 [+] completed,cost 8505ms with result:pyc file handled:output_2385117/crackme4 :__init__.py:167-20  /usr/local/lib/python3.8/dist-packages/pydumpck/py_common_dump/__init__.py on(__init__.statistics_status) at 762@MainThread  
